<?xml version="1.0"?>
<robot name="robot_kol">

    <material name="red">
        <color rgba="1 0 0 1" />
    </material>
    <material name="green">
        <color rgba="0 1 0 1" />
    </material>
    <material name="blue">
        <color rgba="0 0 1 1" />
    </material>

    <link name="base_link"/>

    <joint name="base_link_TO_rail" type="fixed">
        <parent link="base_link" />
        <child link="rail" />
        <origin xyz="0 0 0" rpy="0 0 0" />
    </joint>

    <link name="rail">
        <visual>
            <geometry>
                <box size="0.4 0.2 0.05" />
            </geometry>
            <material name="blue"/>
        </visual>
    </link>

    <joint name="rail_TO_slider" type="prismatic">
        <parent link="rail" />
        <child link="slider" />
        <origin xyz="0 0 0.035" rpy="0 0 0" />
        <axis xyz="1 0 0" />
        <limit lower="-0.175" upper="0.175" effort="100" velocity="100" />
    </joint>

    <link name="slider">
        <visual>
            <geometry>
                <box size="0.1 0.1 0.02" />
            </geometry>
            <material name="red"/>
        </visual>
    </link>

    <joint name="slider_TO_first_arm" type="fixed">
        <parent link="slider" />
        <child link="first_arm" />
        <origin xyz="0 0 0.12" rpy="0 0 0" />
    </joint>

    <link name="first_arm">
        <visual>
            <geometry>
                <cylinder radius="0.02" length="0.2" />
            </geometry>
            <material name="green"/>
        </visual>
    </link>

    <joint name="first_arm_TO_second_arm" type="revolute">
        <parent link="first_arm" />
        <child link="second_arm" />
        <origin xyz="0 0 0.1" rpy="0 0 0" />
        <axis xyz="0 1 0" />
        <limit lower="0.0" upper="1.57" effort="100" velocity="100" />
    </joint>

    <link name="second_arm">
        <visual>
            <origin xyz="0 0 0.1" rpy="0 0 0" />
            <geometry>
                <cylinder radius="0.02" length="0.2" />
            </geometry>
            <material name="red"/>
        </visual>
    </link>
</robot>
